<mujoco model="xlerobot">
  <compiler angle="radian" meshdir="./assets/"/>

  <asset>
    <material name="orange" rgba="1.0 0.331 0.0 1.0" specular="0.1" shininess="0.1"/>
    <material name="black" rgba="0.1 0.1 0.1 1.0" specular="0.1" shininess="0.1"/>

    <mesh name="Base" file="Base.stl"/>
    <mesh name="Base_Motor" file="Base_Motor.stl"/>
    <mesh name="Rotation_Pitch" file="Rotation_Pitch.stl"/>
    <mesh name="Rotation_Pitch_Motor" file="Rotation_Pitch_Motor.stl"/>
    <mesh name="Upper_Arm" file="Upper_Arm.stl"/>
    <mesh name="Upper_Arm_Motor" file="Upper_Arm_Motor.stl"/>
    <mesh name="Lower_Arm" file="Lower_Arm.stl"/>
    <mesh name="Lower_Arm_Motor" file="Lower_Arm_Motor.stl"/>
    <mesh name="Wrist_Pitch_Roll" file="Wrist_Pitch_Roll.stl"/>
    <mesh name="Wrist_Pitch_Roll_Motor" file="Wrist_Pitch_Roll_Motor.stl"/>
    <mesh name="Fixed_Jaw_part1" file="Fixed_Jaw_part1.stl"/>
    <mesh name="Fixed_Jaw_part2" file="Fixed_Jaw_part2.stl"/>
    <mesh name="Moving_Jaw_part1" file="Moving_Jaw_part1.stl"/>
    <mesh name="Moving_Jaw_part2" file="Moving_Jaw_part2.stl"/>
    <mesh name="Moving_Jaw_part3" file="Moving_Jaw_part3.stl"/>

    <mesh name="drive_motor_mount-v4-3" file="drive_motor_mount-v4-3.stl" scale="0.001 0.001 0.001" />
    <mesh name="base_plate_layer1-v5-1" file="base_plate_layer1-v5-1.stl" scale="0.001 0.001 0.001" />
    <mesh name="ST3215_Servo_Motor-v1-2" file="ST3215_Servo_Motor-v1-2.stl" scale="0.001 0.001 0.001" />
    <mesh name="3_8-Hex-Bore-Plastic-VersaHub-217-5828-v2-2" file="3_8-Hex-Bore-Plastic-VersaHub-217-5828-v2-2.stl" scale="0.001 0.001 0.001" />
    <mesh name="4-Omni-Directional-Wheel_Single_Body-v1-2" file="simplify_4-Omni-Directional-Wheel_Single_Body-v1-2.stl" scale="0.001 0.001 0.001" />
    <mesh name="drive_motor_mount-v4-2" file="drive_motor_mount-v4-2.stl" scale="0.001 0.001 0.001" />
    <mesh name="ST3215_Servo_Motor-v1-1" file="ST3215_Servo_Motor-v1-1.stl" scale="0.001 0.001 0.001" />
    <mesh name="3_8-Hex-Bore-Plastic-VersaHub-217-5828-v2-1" file="3_8-Hex-Bore-Plastic-VersaHub-217-5828-v2-1.stl" scale="0.001 0.001 0.001" />
    <mesh name="4-Omni-Directional-Wheel_Single_Body-v1-1" file="simplify_4-Omni-Directional-Wheel_Single_Body-v1-1.stl" scale="0.001 0.001 0.001" />
    <mesh name="drive_motor_mount-v4-1" file="drive_motor_mount-v4-1.stl" scale="0.001 0.001 0.001" />
    <mesh name="ST3215_Servo_Motor-v1" file="ST3215_Servo_Motor-v1.stl" scale="0.001 0.001 0.001" />
    <mesh name="3_8-Hex-Bore-Plastic-VersaHub-217-5828-v2" file="3_8-Hex-Bore-Plastic-VersaHub-217-5828-v2.stl" scale="0.001 0.001 0.001" />
    <mesh name="4-Omni-Directional-Wheel_Single_Body-v1" file="simplify_4-Omni-Directional-Wheel_Single_Body-v1.stl" scale="0.001 0.001 0.001" />
    <mesh name="servo_controller_mount-v1" file="servo_controller_mount-v1.stl" scale="0.001 0.001 0.001" />
    <mesh name="lipo_battery_mount-v1" file="lipo_battery_mount-v1.stl" scale="0.001 0.001 0.001" />
    <mesh name="Battery---Battery-5.2-Ah-DC5521-Plug-v2" file="Battery---Battery-5.2-Ah-DC5521-Plug-v2.stl" scale="0.001 0.001 0.001" />
    <mesh name="94868A713_NO-THREADS_Female-Threaded-Hex-Standoff" file="94868A713_NO-THREADS_Female-Threaded-Hex-Standoff.stl" scale="0.001 0.001 0.001" />
    <mesh name="base_plate_layer2-v1" file="base_plate_layer2-v1.stl" scale="0.001 0.001 0.001" />
  </asset>

  <default>
    <default class="so_arm100">
      <joint frictionloss="0.1" armature="0.1"/>
      <position kp="50" dampratio="1" forcerange="-35 35" ctrlrange="-3.14158 3.14158"/>
      <default class="Rotation">
        <joint axis="0 1 0" range="-2.2 2.2"/>
      </default>
      <default class="Pitch">
        <joint axis="1 0 0" range="-3.14158 0.2"/>
      </default>
      <default class="Elbow">
        <joint axis="1 0 0" range="0 3.14158"/>
      </default>
      <default class="Wrist_Pitch">
        <joint axis="1 0 0" range="-2.0 1.8"/>
      </default>
      <default class="Wrist_Roll">
        <joint axis="0 1 0" range="-3.14158 3.14158"/>
      </default>
      <default class="Jaw">
        <joint axis="0 0 1" range="-0.2 2.0"/>
      </default>
      <default class="visual">
        <geom type="mesh" contype="0" conaffinity="0" density="0" group="2" material="black"/>
        <default class="motor_visual">
          <geom material="black"/>
        </default>
      </default>
      <default class="collision">
        <geom group="3" type="mesh"/>
        <default class="finger_collision">
          <geom type="box" solimp="2 1 0.01" solref="0.01 1" friction="1 0.005 0.0001"/>
        </default>
      </default>
    </default>
  </default>

  <tendon>
    <fixed name="slider_actuator_x">
      <joint joint="ST3215_Servo_Motor-v1-2_Hub---Servo" coef="0"/>
      <joint joint="ST3215_Servo_Motor-v1-1_Hub-2---Servo" coef="-0.5"/>
      <joint joint="ST3215_Servo_Motor-v1_Revolute-40" coef="0.5"/>
    </fixed>
    
    <fixed name="slide">
      <joint joint="ST3215_Servo_Motor-v1-2_Hub---Servo" coef="0.0"/>
      <joint joint="ST3215_Servo_Motor-v1-1_Hub-2---Servo" coef="0.286"/>
      <joint joint="ST3215_Servo_Motor-v1_Revolute-40" coef="-0.286"/>
    </fixed>
    
    <fixed name="rotate">
      <joint joint="ST3215_Servo_Motor-v1-2_Hub---Servo" coef="0.33"/>
      <joint joint="ST3215_Servo_Motor-v1-1_Hub-2---Servo" coef="0.33"/>
      <joint joint="ST3215_Servo_Motor-v1_Revolute-40" coef="0.33"/>
    </fixed>
  </tendon>

  <worldbody>
    <light directional="true" pos="-0.5 0.5 3" dir="0 0 -1" />
    <body name="chassis" pos="0 0 0.035" quat="0.707108 0 0 0.707108">
      <joint name="slide_joint_x" type="slide" axis="1 0 0" damping="0.1"/>
      <joint name="slide_joint_y" type="slide" axis="0 1 0" damping="0.1"/>
      <joint name="hinge_joint_z" type="hinge" axis="0 0 1" damping="0.1"/>
      <geom type="box" size="0.2 0.2 0.38" pos="-0.03 0 0.44" rgba="0.2 0.2 0.6 0.2"/>

      <body name="base_plate_layer1-v5-1" pos="0.0 0.0 0.0" euler="0.0 0.0 -1.5708">
        <geom name="base_plate_layer1-v5-1_geom" type="mesh" mesh="base_plate_layer1-v5-1" rgba="0.1 0.1 0.1 1" />
        <inertial mass="1.9468624348344596" pos="-4.730687660675253e-15 -2.7155537377808555e-05 -0.0035000000000000005" fullinertia="0.005637109888809055 0.005628440956780792 0.0112496514690387 1.3447333053523504e-16 1.7848833522297417e-20 2.6469779601696886e-23" />
        <body name="drive_motor_mount-v4-3" pos="-0.020610000007450578 -0.09 0.0020000000000000018" euler="-0.0 0.0 -1.5707963267948966">
          <geom name="drive_motor_mount-v4-3_geom" type="mesh" mesh="drive_motor_mount-v4-3" rgba="0.1 0.1 0.1 1" />
          <inertial mass="0.035884017191401885" pos="0.00017900181977195112 -0.0006914486154622601 0.0004348187449640745" fullinertia="3.2235542654871883e-06 3.901284246443171e-06 6.890721819180175e-06 -1.4488185386067676e-08 -3.4701845947883736e-08 1.0877684749210782e-07" />
          <body name="ST3215_Servo_Motor-v1-2" pos="0.00959999999999999 -0.004889999992549421 0.01436" euler="-6.123233995736766e-17 0.0 -1.5707963267948968">
            <geom name="ST3215_Servo_Motor-v1-2_geom" type="mesh" mesh="ST3215_Servo_Motor-v1-2" rgba="0.1 0.1 0.1 1" friction="0.001 0.0001 0.0001"/>
            <inertial mass="0.0658962961901927" pos="-0.014664257020729004 -0.008722816656342332 1.2191853053420506e-06" fullinertia="1.0300908387946657e-05 1.3913691655689984e-05 1.8215748982019662e-05 1.1951581712694353e-07 -1.7998869276644268e-09 8.88550145137008e-10" />
            <body name="3_8-Hex-Bore-Plastic-VersaHub-217-5828-v2-2" pos="-0.025500000000000002 0.011187500000000003 2.220446049250313e-18" euler="-1.5707963267948966 1.5192908393215678e-64 3.141592653589793">
              <joint name="ST3215_Servo_Motor-v1-2_Hub---Servo" type="hinge" axis="6.887535064975403e-49 -3.749399456654644e-33 1.0" pos="-4.4408920985006255e-18 -3.469446951953615e-18 -0.0015874999999999917"/>
              <geom name="3_8-Hex-Bore-Plastic-VersaHub-217-5828-v2-2_geom" type="mesh" mesh="3_8-Hex-Bore-Plastic-VersaHub-217-5828-v2-2" rgba="0.1 0.1 0.1 1" friction="0.001 0.0001 0.0001"/>
              <inertial mass="0.08665496109754897" pos="8.50877658112488e-09 7.358945011137765e-09 0.0023811166424899887" fullinertia="1.2296291761641504e-05 1.2296276073121143e-05 2.2911778015411222e-05 -3.19167294920219e-12 1.755992026942528e-12 1.5186622033709633e-12" />
              <body name="4-Omni-Directional-Wheel_Single_Body-v1-2" pos="-2.453269466693399e-18 0.0 0.0174625" euler="-3.141592653589793 -1.5192908393215678e-64 -0.2617993877991494">
                <geom name="4-Omni-Directional-Wheel_Single_Body-v1-2_geom" type="mesh" mesh="4-Omni-Directional-Wheel_Single_Body-v1-2" rgba="0.1 0.1 0.1 1" friction="0.001 0.0001 0.0001"/>
                <inertial mass="1.3542854082324305" pos="-7.105207895657716e-08 -1.1369917947312704e-07 -1.2090586078983279e-08" fullinertia="0.0010936200374455458 0.0010936108480286116 0.0018798127501507855 -5.245142023675448e-09 4.046730352778215e-10 1.0004485488405523e-10" />
              </body>
            </body>
          </body>
        </body>
        <body name="drive_motor_mount-v4-2" pos="0.08824728634432479 0.027151216421550314 0.001999999999999993" euler="-0.0 0.0 0.5235987755982997">
          <geom name="drive_motor_mount-v4-2_geom" type="mesh" mesh="drive_motor_mount-v4-2" rgba="0.1 0.1 0.1 1" />
          <inertial mass="0.035884017191401885" pos="0.00017900181977194513 -0.0006914486154622601 0.00043481874496407525" fullinertia="3.2235542654872044e-06 3.901284246443212e-06 6.890721819180191e-06 -1.4488185386052894e-08 -3.470184594788067e-08 1.0877684749210813e-07" />
          <body name="ST3215_Servo_Motor-v1-1" pos="0.010400000000000081 -0.004889999992549394 0.014359999999999984" euler="-6.406864442435952e-17 -7.857775794700331e-16 -1.570796326794897">
            <geom name="ST3215_Servo_Motor-v1-1_geom" type="mesh" mesh="ST3215_Servo_Motor-v1-1" rgba="0.1 0.1 0.1 1" friction="0.001 0.0001 0.0001"/>
            <inertial mass="0.0658962961901927" pos="-0.014664257020728995 -0.008722816656342374 1.2191853053600496e-06" fullinertia="1.0300908387946253e-05 1.391369165569022e-05 1.8215748982019256e-05 1.1951581712706042e-07 -1.7998869276893484e-09 8.885501451146896e-10" />
            <body name="3_8-Hex-Bore-Plastic-VersaHub-217-5828-v2-1" pos="-0.02550000000000004 0.011187499999999986 0.0" euler="-1.5707963267948966 2.220446049250324e-16 1.6021677874353734e-16">
              <joint name="ST3215_Servo_Motor-v1-1_Hub-2---Servo" type="hinge" axis="-2.018922194424455e-07 5.551115123125783e-17 0.9999996503124187" pos="1.0279185592260934e-07 6.850769951327593e-18 -0.0015873219592831226" />
              <geom name="3_8-Hex-Bore-Plastic-VersaHub-217-5828-v2-1_geom" type="mesh" mesh="3_8-Hex-Bore-Plastic-VersaHub-217-5828-v2-1" rgba="0.1 0.1 0.1 1" friction="0.001 0.0001 0.0001"/>
              <inertial mass="0.08665496109754897" pos="8.508776579152501e-09 7.358945011269938e-09 0.0023811166424899787" fullinertia="1.2296291761641589e-05 1.2296276073121566e-05 2.2911778015411107e-05 -3.1916729680995547e-12 1.755991986238418e-12 1.5186621750295066e-12" />
              <body name="4-Omni-Directional-Wheel_Single_Body-v1-1" pos="-8.88178419700111e-18 3.3306690738754695e-17 0.01746250000000007" euler="3.141592653589793 5.5511151231257747e-17 1.8325957145940461">
                <geom name="4-Omni-Directional-Wheel_Single_Body-v1-1_geom" type="mesh" mesh="4-Omni-Directional-Wheel_Single_Body-v1-1" rgba="0.1 0.1 0.1 1" friction="0.001 0.0001 0.0001"/>
                <inertial mass="1.3542854082324305" pos="-7.105207896524954e-08 -1.1369917948959942e-07 -1.2090586104095832e-08" fullinertia="0.0010936200374455313 0.0010936108480285981 0.0018798127501507892 -5.2451420243259696e-09 4.0467303541420525e-10 1.0004485627777097e-10" />
              </body>
            </body>
          </body>
        </body>
        <body name="drive_motor_mount-v4-1" pos="-0.06763728633687423 0.06284878357844971 0.0020000000000000018" euler="5.415442118703716e-17 -1.3598996028091536e-16 2.617993877991494">
          <geom name="drive_motor_mount-v4-1_geom" type="mesh" mesh="drive_motor_mount-v4-1" rgba="0.1 0.1 0.1 1" />
          <inertial mass="0.035884017191401885" pos="0.0001790018197719455 -0.0006914486154622614 0.0004348187449640748" fullinertia="3.2235542654871925e-06 3.901284246443185e-06 6.890721819180079e-06 -1.4488185386019653e-08 -3.470184594788136e-08 1.087768474921115e-07" />
          <body name="ST3215_Servo_Motor-v1" pos="0.00959999999999999 -0.004889999992549434 0.014360000000000013" euler="2.2863854877850107e-16 -1.2117128698533114e-16 -1.5707963267948966">
            <geom name="ST3215_Servo_Motor-v1_geom" type="mesh" mesh="ST3215_Servo_Motor-v1" rgba="0.1 0.1 0.1 1" friction="0.001 0.0001 0.0001"/>
            <inertial mass="0.0658962961901927" pos="-0.014664257020729005 -0.00872281665634233 1.2191853053530741e-06" fullinertia="1.0300908387946575e-05 1.3913691655689957e-05 1.821574898201946e-05 1.1951581712691303e-07 -1.7998869276903668e-09 8.885501451354187e-10" />
            <body name="3_8-Hex-Bore-Plastic-VersaHub-217-5828-v2" pos="-0.02549999999999999 0.011187500000000003 -8.881784197001253e-18" euler="-1.5707963267948966 2.4155320165495564e-32 1.570796326794897">
              <joint name="ST3215_Servo_Motor-v1_Revolute-40" type="hinge" axis="-1.2961506867803505e-16 -2.018922189983563e-07 0.9999996503124184" pos="2.796134304347991e-17 1.2953369686987196e-08 -0.0015874775641056748" />
              <geom name="3_8-Hex-Bore-Plastic-VersaHub-217-5828-v2_geom" type="mesh" mesh="3_8-Hex-Bore-Plastic-VersaHub-217-5828-v2" rgba="0.1 0.1 0.1 1" friction="0.001 0.0001 0.0001"/>
              <inertial mass="0.08665496109754897" pos="8.508776583007207e-09 7.358945014555165e-09 0.0023811166424899874" fullinertia="1.2296291761641274e-05 1.2296276073121517e-05 2.291177801541124e-05 -3.1916729470190563e-12 1.7559920314671269e-12 1.5186621186676676e-12" />
              <body name="4-Omni-Directional-Wheel_Single_Body-v1" pos="-2.220446049250313e-18 -7.105427357601001e-17 0.017462499999999947" euler="-3.141592653589793 6.689058043222894e-18 -0.2617993877991494">
                <geom name="4-Omni-Directional-Wheel_Single_Body-v1_geom" type="mesh" mesh="4-Omni-Directional-Wheel_Single_Body-v1" rgba="0.1 0.1 0.1 1" friction="0.001 0.0001 0.0001"/>
                <inertial mass="1.3542854082324305" pos="-7.105207895771595e-08 -1.1369917947234093e-07 -1.2090586101420118e-08" fullinertia="0.0010936200374455356 0.0010936108480285988 0.0018798127501507824 -5.245142023187557e-09 4.046730340142343e-10 1.0004485862393181e-10" />
              </body>
            </body>
          </body>
        </body>
        <body name="servo_controller_mount-v1" pos="0.0 0.06 0.0029999999999999983" euler="-0.0 0.0 -0.0">
          <geom name="servo_controller_mount-v1_geom" type="mesh" mesh="servo_controller_mount-v1" rgba="0.1 0.1 0.1 1" />
          <inertial mass="0.06175589411431898" pos="-3.6769132064861433e-14 0.0 -0.0012090515491760903" fullinertia="1.0761471541836937e-05 1.8890192778258753e-05 2.9413765100515303e-05 2.602085214051591e-22 -6.608103581422321e-19 1.6940658945086007e-21" />
        </body>
        <body name="lipo_battery_mount-v1" pos="-0.05 -0.02 0.0" euler="-0.0 0.0 1.5707963267948968">
          <geom name="lipo_battery_mount-v1_geom" type="mesh" mesh="lipo_battery_mount-v1" rgba="0.1 0.1 0.1 1" />
          <inertial mass="0.1653518573066047" pos="-4.0023770071114873e-16 -0.003034408758946965 0.003481111705280585" fullinertia="9.882008372625315e-05 7.479150401991051e-05 0.0001696386060861471 4.0216183619824973e-19 -1.283332239482784e-19 2.263422861539775e-06" />
          <body name="Battery---Battery-5.2-Ah-DC5521-Plug-v2" pos="2.220446049250313e-18 0.036499999999999984 0.003000000000000007" euler="-1.5707963267948966 6.123233995736767e-17 -1.5707963267948966">
            <geom name="Battery---Battery-5.2-Ah-DC5521-Plug-v2_geom" type="mesh" mesh="Battery---Battery-5.2-Ah-DC5521-Plug-v2" rgba="0.1 0.1 0.1 1" />
            <inertial mass="1.2215469988184764" pos="0.020000000000000018 -8.300646300726007e-05 -0.03492202423172039" fullinertia="0.0008162228074590446 0.00065975897252246 0.00047597821218279645 1.3010426069826053e-18 4.3368086899420163e-19 3.135378714781114e-06" />
          </body>
        </body>
        <body name="94868A713_NO-THREADS_Female-Threaded-Hex-Standoff" pos="0.0 1.3010426069826053e-18 0.025" euler="-0.0 0.0 -0.0">
          <geom name="94868A713_NO-THREADS_Female-Threaded-Hex-Standoff_geom" type="mesh" mesh="94868A713_NO-THREADS_Female-Threaded-Hex-Standoff" rgba="0.1 0.1 0.1 1" />
          <inertial mass="0.006150070863406618" pos="2.1864399078485972e-14 -1.2010287423717232e-09 -6.6970201384464195e-09" fullinertia="1.0965196650850464e-06 1.096519654894581e-06 1.837396493115053e-08 3.0209076389532564e-20 2.6974127807751317e-18 -9.149560120561933e-14" />
        </body>
        <body name="base_plate_layer2-v1" pos="0.0 -6.430841866638185e-19 0.056999999999999995" euler="-0.0 0.0 -0.0">
          <geom name="base_plate_layer2-v1_geom" type="mesh" mesh="base_plate_layer2-v1" rgba="0.1 0.1 0.1 1" />
          <inertial mass="1.9468624348344596" pos="-4.730687660675253e-15 -2.7155537377808555e-05 -0.0034999999999999966" fullinertia="0.0056371098888090545 0.005628440956780792 0.0112496514690387 1.3447333053523506e-16 1.7848833522266602e-20 0.0" />
        </body>
      </body>
      <body name="Rotation_Pitch" pos="0.1352 -0.15 0.7865" quat="0.499998 0.5 0.500002 0.5">
        <inertial pos="-9.07886e-05 0.0590972 0.031089" quat="0.363978 0.441169 -0.623108 0.533504" mass="0.119226" diaginertia="5.94278e-05 5.89975e-05 3.13712e-05"/>
        <joint name="Rotation_L" pos="0 0 0" axis="0 -1 0" range="-2.1 2.1"/>
        <geom type="mesh" rgba="0.3 0.3 0.3 1" mesh="Rotation_Pitch"/>
        <geom type="mesh" rgba="0.3 0.3 0.3 1" mesh="Rotation_Pitch_Motor"/>
        <body name="Upper_Arm" pos="0 0.1025 0.0306" quat="0.707105 0.707108 0 0">
          <inertial pos="-1.72052e-05 0.0701802 0.00310545" quat="0.50104 0.498994 -0.493562 0.50632" mass="0.162409" diaginertia="0.000213312 0.000167164 7.01522e-05"/>
          <joint name="Pitch_L" pos="0 0 0" axis="-1 0 0" range="-0.1 3.45"/>
          <geom type="mesh" rgba="0.3 0.3 0.3 1" mesh="Upper_Arm"/>
          <geom type="mesh" rgba="0.3 0.3 0.3 1" mesh="Upper_Arm_Motor"/>
          <body name="Lower_Arm" pos="0 0.11257 0.028" quat="0.707105 -0.707108 0 0">
            <inertial pos="-0.00339604 0.00137796 0.0768007" quat="0.701995 0.0787996 0.0645626 0.704859" mass="0.147968" diaginertia="0.000138803 0.000107748 4.84242e-05"/>
            <joint name="Elbow_L" pos="0 0 0" axis="1 0 0" range="-0.2 3.14159"/>
            <geom type="mesh" rgba="0.3 0.3 0.3 1" mesh="Lower_Arm"/>
            <geom type="mesh" rgba="0.3 0.3 0.3 1" mesh="Lower_Arm_Motor"/>
            <body name="Wrist_Pitch_Roll" pos="0 0.0052 0.1349" quat="0.707105 -0.707108 0 0">
              <inertial pos="-0.00852653 -0.0352279 -2.34622e-05" quat="-0.0522806 0.705235 0.0549524 0.704905" mass="0.0661321" diaginertia="3.45403e-05 2.39041e-05 1.94704e-05"/>
              <joint name="Wrist_Pitch_L" pos="0 0 0" axis="1 0 0" range="-1.8 1.8"/>
              <geom type="mesh" rgba="0.3 0.3 0.3 1" mesh="Wrist_Pitch_Roll"/>
              <geom type="mesh" rgba="0.3 0.3 0.3 1" mesh="Wrist_Pitch_Roll_Motor"/>
              <body name="Fixed_Jaw" pos="0 -0.0601 0" quat="0.707105 0 0.707108 0">
                <inertial pos="0.00552377 -0.0280167 0.000483583" quat="0.41836 0.620891 -0.350644 0.562599" mass="0.0929859" diaginertia="5.03136e-05 4.64098e-05 2.72961e-05"/>
                <joint name="Wrist_Roll_L" pos="0 0 0" axis="0 -1 0" range="-3.14159 3.14159"/>
                <geom type="mesh" rgba="0.3 0.3 0.3 1" mesh="Fixed_Jaw_part1"/>
                <geom type="mesh" rgba="0.3 0.3 0.3 1" mesh="Fixed_Jaw_part2"/>
                <body name="Moving_Jaw" pos="-0.0202 -0.0244 0" quat="3.45518e-07 -0.0940644 0.995566 -3.65692e-06">
                  <inertial pos="-0.00161745 -0.0303473 0.000449646" quat="0.696562 0.716737 -0.0239844 -0.0227026" mass="0.0202444" diaginertia="1.11265e-05 8.99651e-06 2.99548e-06"/>
                  <joint name="Jaw_L" pos="0 0 0" axis="0 0 1" range="-3.14159 3.14159"/>
                  <geom type="mesh" rgba="0.1 0.1 0.1 1" mesh="Moving_Jaw_part1"/>
                  <geom type="mesh" rgba="0.1 0.1 0.1 1" mesh="Moving_Jaw_part2"/>
                  <geom type="mesh" rgba="0.1 0.1 0.1 1" mesh="Moving_Jaw_part3"/>
                </body>
              </body>
            </body>
          </body>
        </body>
      </body>
      <body name="Rotation_Pitch_R" pos="0.1352 0.15 0.7865" quat="0.499998 0.5 0.500002 0.5">
        <inertial pos="-9.07886e-05 0.0590972 0.031089" quat="0.363978 0.441169 -0.623108 0.533504" mass="0.119226" diaginertia="5.94278e-05 5.89975e-05 3.13712e-05"/>
        <joint name="Rotation_R" pos="0 0 0" axis="0 -1 0" range="-2.1 2.1"/>
        <geom type="mesh" rgba="0.3 0.3 0.3 1" mesh="Rotation_Pitch"/>
        <geom type="mesh" rgba="0.3 0.3 0.3 1" mesh="Rotation_Pitch_Motor"/>
        <body name="Upper_Arm_2" pos="0 0.1025 0.0306" quat="0.707105 0.707108 0 0">
          <inertial pos="-1.72052e-05 0.0701802 0.00310545" quat="0.50104 0.498994 -0.493562 0.50632" mass="0.162409" diaginertia="0.000213312 0.000167164 7.01522e-05"/>
          <joint name="Pitch_R" pos="0 0 0" axis="-1 0 0" range="-0.1 3.45"/>
          <geom type="mesh" rgba="0.3 0.3 0.3 1" mesh="Upper_Arm"/>
          <geom type="mesh" rgba="0.3 0.3 0.3 1" mesh="Upper_Arm_Motor"/>
          <body name="Lower_Arm_2" pos="0 0.11257 0.028" quat="0.707105 -0.707108 0 0">
            <inertial pos="-0.00339604 0.00137796 0.0768007" quat="0.701995 0.0787996 0.0645626 0.704859" mass="0.147968" diaginertia="0.000138803 0.000107748 4.84242e-05"/>
            <joint name="Elbow_R" pos="0 0 0" axis="1 0 0" range="-0.2 3.14159"/>
            <geom type="mesh" rgba="0.3 0.3 0.3 1" mesh="Lower_Arm"/>
            <geom type="mesh" rgba="0.3 0.3 0.3 1" mesh="Lower_Arm_Motor"/>
            <body name="Wrist_Pitch_Roll_2" pos="0 0.0052 0.1349" quat="0.707105 -0.707108 0 0">
              <inertial pos="-0.00852653 -0.0352279 -2.34622e-05" quat="-0.0522806 0.705235 0.0549524 0.704905" mass="0.0661321" diaginertia="3.45403e-05 2.39041e-05 1.94704e-05"/>
              <joint name="Wrist_Pitch_R" pos="0 0 0" axis="1 0 0" range="-1.8 1.8"/>
              <geom type="mesh" rgba="0.3 0.3 0.3 1" mesh="Wrist_Pitch_Roll"/>
              <geom type="mesh" rgba="0.3 0.3 0.3 1" mesh="Wrist_Pitch_Roll_Motor"/>
              <body name="Fixed_Jaw_2" pos="0 -0.0601 0" quat="0.707105 0 0.707108 0">
                <inertial pos="0.00552377 -0.0280167 0.000483583" quat="0.41836 0.620891 -0.350644 0.562599" mass="0.0929859" diaginertia="5.03136e-05 4.64098e-05 2.72961e-05"/>
                <joint name="Wrist_Roll_R" pos="0 0 0" axis="0 -1 0" range="-3.14159 3.14159"/>
                <geom type="mesh" rgba="0.3 0.3 0.3 1" mesh="Fixed_Jaw_part1"/>
                <geom type="mesh" rgba="0.3 0.3 0.3 1" mesh="Fixed_Jaw_part2"/>
                <body name="Moving_Jaw_2" pos="-0.0202 -0.0244 0" quat="3.45518e-07 -0.0940644 0.995566 -3.65692e-06">
                  <inertial pos="-0.00161745 -0.0303473 0.000449646" quat="0.696562 0.716737 -0.0239844 -0.0227026" mass="0.0202444" diaginertia="1.11265e-05 8.99651e-06 2.99548e-06"/>
                  <joint name="Jaw_R" pos="0 0 0" axis="0 0 1" range="-3.14159 3.14159"/>
                  <geom type="mesh" rgba="0.1 0.1 0.1 1" mesh="Moving_Jaw_part1"/>
                  <geom type="mesh" rgba="0.1 0.1 0.1 1" mesh="Moving_Jaw_part2"/>
                  <geom type="mesh" rgba="0.1 0.1 0.1 1" mesh="Moving_Jaw_part3"/>
                </body>
              </body>
            </body>
          </body>
        </body>
      </body>
      <body name="head_pan_link" pos="-0.125 0 0.91">
        <inertial pos="0 0 0" quat="0.514814 0.545129 -0.452957 0.482318" mass="2.2556" diaginertia="0.0184878 0.0128242 0.00948808"/>
        <joint name="head_pan_joint" pos="0 0 0" axis="0 0 1" range="-1.57 1.57" actuatorfrcrange="-0.32 0.32"/>
        <body name="head_tilt_link" pos="0.05 0 0.18">
          <inertial pos="0.0081 0.0025 0.0113" quat="0.645806 0.659961 -0.274048 0.268857" mass="0.9087" diaginertia="0.00630102 0.00590111 0.00139787"/>
          <joint name="head_tilt_joint" pos="0 0 0" axis="0 1 0" range="-0.76 1.45" actuatorfrcrange="-0.68 0.68"/>
        </body>
      </body>
    </body>
  </worldbody>
  
  <actuator>
    <velocity name="slider_actuator_x" joint="slide_joint_x" kv="10"/>
    <velocity name="slider_actuator_y" joint="slide_joint_y" kv="10"/>
    <velocity name="hinge_actuator_z" joint="hinge_joint_z" kv="10"/>

    <position class="Rotation" name="Rotation_R" joint="Rotation_R"/>
    <position class="Pitch" name="Pitch_R" joint="Pitch_R"/>
    <position class="Elbow" name="Elbow_R" joint="Elbow_R"/>
    <position class="Wrist_Pitch" name="Wrist_Pitch_R" joint="Wrist_Pitch_R"/>
    <position class="Wrist_Roll" name="Wrist_Roll_R" joint="Wrist_Roll_R"/>
    <position class="Jaw" name="Jaw_R" joint="Jaw_R"/>

    <position class="Rotation" name="Rotation_L" joint="Rotation_L"/>
    <position class="Pitch" name="Pitch_L" joint="Pitch_L"/>
    <position class="Elbow" name="Elbow_L" joint="Elbow_L"/>
    <position class="Wrist_Pitch" name="Wrist_Pitch_L" joint="Wrist_Pitch_L"/>
    <position class="Wrist_Roll" name="Wrist_Roll_L" joint="Wrist_Roll_L"/>
    <position class="Jaw" name="Jaw_L" joint="Jaw_L"/>

    <velocity name="wheel1" joint="ST3215_Servo_Motor-v1-2_Hub---Servo" kv="10"/>
    <velocity name="wheel2" joint="ST3215_Servo_Motor-v1-1_Hub-2---Servo" kv="10"/>
    <velocity name="wheel3" joint="ST3215_Servo_Motor-v1_Revolute-40" kv="10"/>

  </actuator>
</mujoco>
